module,execution_time (sec),success,timestamp,error,error_short
cowidev.vax.batch.argentina,4.11,True,2022-10-15T07:00:17,,
cowidev.vax.batch.australia,2.16,True,2022-10-15T07:00:15,,
cowidev.vax.batch.austria,3.15,True,2022-10-15T07:00:16,,
cowidev.vax.batch.belgium,2.86,True,2022-10-15T07:00:16,,
cowidev.vax.batch.bolivia,2.56,True,2022-10-15T07:00:15,,
cowidev.vax.batch.canada,6.4,True,2022-10-15T07:00:21,,
cowidev.vax.batch.chile,1.29,True,2022-10-15T07:00:17,,
cowidev.vax.batch.czechia,4.01,True,2022-10-15T07:00:20,,
cowidev.vax.batch.denmark,4.74,True,2022-10-15T07:00:21,,
cowidev.vax.batch.ecdc,164.3,True,2022-10-15T07:03:01,,
cowidev.vax.batch.ecuador,1.52,True,2022-10-15T07:00:18,,
cowidev.vax.batch.estonia,0.95,True,2022-10-15T07:00:19,,
cowidev.vax.batch.france,0.52,True,2022-10-15T07:00:20,,
cowidev.vax.batch.germany,2.18,True,2022-10-15T07:00:22,,
cowidev.vax.batch.greece,3.06,True,2022-10-15T07:00:23,,
cowidev.vax.batch.hong_kong,14.7,True,2022-10-15T07:00:35,,
cowidev.vax.batch.indonesia,,,2022-10-15T07:00:21,,
cowidev.vax.batch.ireland,0.33,True,2022-10-15T07:00:22,,
cowidev.vax.batch.israel,7.98,True,2022-10-15T07:00:30,,
cowidev.vax.batch.italy,14.54,True,2022-10-15T07:00:36,,
cowidev.vax.batch.japan,1.3,False,2022-10-15T07:03:56,"Traceback (most recent call last):
  File ""/mnt/owid_live_covid/covid-19-data/scripts/src/cowidev/cmd/commons/get.py"", line 46, in run
    module.main()
  File ""/mnt/owid_live_covid/covid-19-data/scripts/src/cowidev/vax/batch/japan.py"", line 236, in main
    Japan().export()
  File ""/mnt/owid_live_covid/covid-19-data/scripts/src/cowidev/vax/batch/japan.py"", line 220, in export
    df = self.read().pipe(self.pipeline_base)
  File ""/mnt/owid_live_covid/covid-19-data/scripts/src/cowidev/vax/batch/japan.py"", line 156, in read
    df_latest = self.read_latest().pipe(self.pipe_latest)
  File ""/mnt/owid_live_covid/covid-19-data/scripts/src/cowidev/vax/batch/japan.py"", line 88, in read_latest
    dfs.append(self._read_xlsx(self.source_url, self.sheets, self.metrics))
  File ""/mnt/owid_live_covid/covid-19-data/scripts/src/cowidev/vax/batch/japan.py"", line 97, in _read_xlsx
    xlsx = pd.ExcelFile(url)
  File ""/mnt/owid_live_covid/covid-19-data/scripts/venv/lib/python3.9/site-packages/pandas/io/excel/_base.py"", line 1191, in __init__
    ext = inspect_excel_format(
  File ""/mnt/owid_live_covid/covid-19-data/scripts/venv/lib/python3.9/site-packages/pandas/io/excel/_base.py"", line 1070, in inspect_excel_format
    with get_handle(
  File ""/mnt/owid_live_covid/covid-19-data/scripts/venv/lib/python3.9/site-packages/pandas/io/common.py"", line 609, in get_handle
    ioargs = _get_filepath_or_buffer(
  File ""/mnt/owid_live_covid/covid-19-data/scripts/venv/lib/python3.9/site-packages/pandas/io/common.py"", line 312, in _get_filepath_or_buffer
    with urlopen(req_info) as req:
  File ""/mnt/owid_live_covid/covid-19-data/scripts/venv/lib/python3.9/site-packages/pandas/io/common.py"", line 212, in urlopen
    return urllib.request.urlopen(*args, **kwargs)
  File ""/home/owid/.pyenv/versions/3.9.6/lib/python3.9/urllib/request.py"", line 214, in urlopen
    return opener.open(url, data, timeout)
  File ""/home/owid/.pyenv/versions/3.9.6/lib/python3.9/urllib/request.py"", line 523, in open
    response = meth(req, response)
  File ""/home/owid/.pyenv/versions/3.9.6/lib/python3.9/urllib/request.py"", line 632, in http_response
    response = self.parent.error(
  File ""/home/owid/.pyenv/versions/3.9.6/lib/python3.9/urllib/request.py"", line 561, in error
    return self._call_chain(*args)
  File ""/home/owid/.pyenv/versions/3.9.6/lib/python3.9/urllib/request.py"", line 494, in _call_chain
    result = func(*args)
  File ""/home/owid/.pyenv/versions/3.9.6/lib/python3.9/urllib/request.py"", line 641, in http_error_default
    raise HTTPError(req.full_url, code, msg, hdrs, fp)
urllib.error.HTTPError: HTTP Error 404: Not Found
",HTTP Error 404: Not Found
cowidev.vax.batch.jersey,2.27,True,2022-10-15T07:00:32,,
cowidev.vax.batch.latvia,36.14,True,2022-10-15T07:01:08,,
cowidev.vax.batch.lithuania,2.01,True,2022-10-15T07:00:37,,
cowidev.vax.batch.luxembourg,4.07,True,2022-10-15T07:00:40,,
cowidev.vax.batch.malaysia,1.1,True,2022-10-15T07:00:38,,
cowidev.vax.batch.malta,0.91,True,2022-10-15T07:00:38,,
cowidev.vax.batch.netherlands,,,2022-10-15T07:00:38,,
cowidev.vax.batch.new_zealand,9.1,True,2022-10-15T07:00:47,,
cowidev.vax.batch.norway,1.3,True,2022-10-15T07:00:40,,
cowidev.vax.batch.peru,3.86,True,2022-10-15T07:00:43,,
cowidev.vax.batch.portugal,,,2022-10-15T07:00:40,,
cowidev.vax.batch.romania,33.34,True,2022-10-15T07:01:14,,
cowidev.vax.batch.saudi_arabia,6.94,True,2022-10-15T07:00:50,,
cowidev.vax.batch.singapore,3.28,True,2022-10-15T07:00:50,,
cowidev.vax.batch.slovakia,101.78,True,2022-10-15T07:02:32,,
cowidev.vax.batch.slovenia,11.48,True,2022-10-15T07:01:02,,
cowidev.vax.batch.south_korea,92.18,True,2022-10-15T07:02:34,,
cowidev.vax.batch.spc,24.21,True,2022-10-15T07:01:32,,
cowidev.vax.batch.sweden,24.94,True,2022-10-15T07:01:39,,
cowidev.vax.batch.switzerland,65.0,True,2022-10-15T07:02:37,,
cowidev.vax.batch.trinidad_and_tobago,2.23,True,2022-10-15T07:01:41,,
cowidev.vax.batch.ukraine,,,2022-10-15T07:01:41,,
cowidev.vax.batch.united_kingdom,10.95,True,2022-10-15T07:01:52,,
cowidev.vax.batch.united_states,74.45,True,2022-10-15T07:03:06,,
cowidev.vax.batch.uruguay,2.59,True,2022-10-15T07:02:34,,
cowidev.vax.batch.zimbabwe,0.47,True,2022-10-15T07:02:34,,
cowidev.vax.incremental.africacdc,,,2022-10-15T07:02:34,,
cowidev.vax.incremental.antigua_barbuda,,,2022-10-15T07:02:34,,
cowidev.vax.incremental.aruba,1.33,True,2022-10-15T07:02:36,,
cowidev.vax.incremental.azerbaijan,,,2022-10-15T07:02:34,,
cowidev.vax.incremental.bahrain,1.92,True,2022-10-15T07:02:36,,
cowidev.vax.incremental.bangladesh,60.08,False,2022-10-15T07:04:56,"Traceback (most recent call last):
  File ""/mnt/owid_live_covid/covid-19-data/scripts/venv/lib/python3.9/site-packages/urllib3/connection.py"", line 174, in _new_conn
    conn = connection.create_connection(
  File ""/mnt/owid_live_covid/covid-19-data/scripts/venv/lib/python3.9/site-packages/urllib3/util/connection.py"", line 96, in create_connection
    raise err
  File ""/mnt/owid_live_covid/covid-19-data/scripts/venv/lib/python3.9/site-packages/urllib3/util/connection.py"", line 86, in create_connection
    sock.connect(sa)
socket.timeout: timed out

During handling of the above exception, another exception occurred:

Traceback (most recent call last):
  File ""/mnt/owid_live_covid/covid-19-data/scripts/venv/lib/python3.9/site-packages/urllib3/connectionpool.py"", line 699, in urlopen
    httplib_response = self._make_request(
  File ""/mnt/owid_live_covid/covid-19-data/scripts/venv/lib/python3.9/site-packages/urllib3/connectionpool.py"", line 394, in _make_request
    conn.request(method, url, **httplib_request_kw)
  File ""/mnt/owid_live_covid/covid-19-data/scripts/venv/lib/python3.9/site-packages/urllib3/connection.py"", line 239, in request
    super(HTTPConnection, self).request(method, url, body=body, headers=headers)
  File ""/home/owid/.pyenv/versions/3.9.6/lib/python3.9/http/client.py"", line 1257, in request
    self._send_request(method, url, body, headers, encode_chunked)
  File ""/home/owid/.pyenv/versions/3.9.6/lib/python3.9/http/client.py"", line 1303, in _send_request
    self.endheaders(body, encode_chunked=encode_chunked)
  File ""/home/owid/.pyenv/versions/3.9.6/lib/python3.9/http/client.py"", line 1252, in endheaders
    self._send_output(message_body, encode_chunked=encode_chunked)
  File ""/home/owid/.pyenv/versions/3.9.6/lib/python3.9/http/client.py"", line 1012, in _send_output
    self.send(msg)
  File ""/home/owid/.pyenv/versions/3.9.6/lib/python3.9/http/client.py"", line 952, in send
    self.connect()
  File ""/mnt/owid_live_covid/covid-19-data/scripts/venv/lib/python3.9/site-packages/urllib3/connection.py"", line 205, in connect
    conn = self._new_conn()
  File ""/mnt/owid_live_covid/covid-19-data/scripts/venv/lib/python3.9/site-packages/urllib3/connection.py"", line 179, in _new_conn
    raise ConnectTimeoutError(
urllib3.exceptions.ConnectTimeoutError: (<urllib3.connection.HTTPConnection object at 0x7f3aa4be1af0>, 'Connection to 103.247.238.92 timed out. (connect timeout=30)')

During handling of the above exception, another exception occurred:

Traceback (most recent call last):
  File ""/mnt/owid_live_covid/covid-19-data/scripts/venv/lib/python3.9/site-packages/requests/adapters.py"", line 440, in send
    resp = conn.urlopen(
  File ""/mnt/owid_live_covid/covid-19-data/scripts/venv/lib/python3.9/site-packages/urllib3/connectionpool.py"", line 755, in urlopen
    retries = retries.increment(
  File ""/mnt/owid_live_covid/covid-19-data/scripts/venv/lib/python3.9/site-packages/urllib3/util/retry.py"", line 574, in increment
    raise MaxRetryError(_pool, url, error or ResponseError(cause))
urllib3.exceptions.MaxRetryError: HTTPConnectionPool(host='103.247.238.92', port=80): Max retries exceeded with url: /webportal/pages/covid19-vaccination-update.php (Caused by ConnectTimeoutError(<urllib3.connection.HTTPConnection object at 0x7f3aa4be1af0>, 'Connection to 103.247.238.92 timed out. (connect timeout=30)'))

During handling of the above exception, another exception occurred:

Traceback (most recent call last):
  File ""/mnt/owid_live_covid/covid-19-data/scripts/src/cowidev/cmd/commons/get.py"", line 46, in run
    module.main()
  File ""/mnt/owid_live_covid/covid-19-data/scripts/src/cowidev/vax/incremental/bangladesh.py"", line 112, in main
    Bangladesh().export()
  File ""/mnt/owid_live_covid/covid-19-data/scripts/src/cowidev/vax/incremental/bangladesh.py"", line 98, in export
    data = self.read().pipe(self.pipeline)
  File ""/mnt/owid_live_covid/covid-19-data/scripts/src/cowidev/vax/incremental/bangladesh.py"", line 24, in read
    soup = get_soup(self.source_url, timeout=30)
  File ""/mnt/owid_live_covid/covid-19-data/scripts/src/cowidev/utils/web/scraping.py"", line 83, in get_soup
    response = get_response(source, request_method, use_proxy, **kwargs)
  File ""/mnt/owid_live_covid/covid-19-data/scripts/src/cowidev/utils/web/scraping.py"", line 49, in get_response
    raise err
  File ""/mnt/owid_live_covid/covid-19-data/scripts/src/cowidev/utils/web/scraping.py"", line 43, in get_response
    response = requests.get(source, **kwargs)
  File ""/mnt/owid_live_covid/covid-19-data/scripts/venv/lib/python3.9/site-packages/requests/api.py"", line 75, in get
    return request('get', url, params=params, **kwargs)
  File ""/mnt/owid_live_covid/covid-19-data/scripts/venv/lib/python3.9/site-packages/requests/api.py"", line 61, in request
    return session.request(method=method, url=url, **kwargs)
  File ""/mnt/owid_live_covid/covid-19-data/scripts/venv/lib/python3.9/site-packages/requests/sessions.py"", line 529, in request
    resp = self.send(prep, **send_kwargs)
  File ""/mnt/owid_live_covid/covid-19-data/scripts/venv/lib/python3.9/site-packages/requests/sessions.py"", line 645, in send
    r = adapter.send(request, **kwargs)
  File ""/mnt/owid_live_covid/covid-19-data/scripts/venv/lib/python3.9/site-packages/requests/adapters.py"", line 507, in send
    raise ConnectTimeout(e, request=request)
requests.exceptions.ConnectTimeout: HTTPConnectionPool(host='103.247.238.92', port=80): Max retries exceeded with url: /webportal/pages/covid19-vaccination-update.php (Caused by ConnectTimeoutError(<urllib3.connection.HTTPConnection object at 0x7f3aa4be1af0>, 'Connection to 103.247.238.92 timed out. (connect timeout=30)'))
","HTTPConnectionPool(host='103.247.238.92', port=80): Max retries exceeded with url: /webportal/pages/covid19-vaccination-update.php (Caused by ConnectTimeoutError(<urllib3.connection.HTTPConnection object at 0x7f3aa4be1af0>, 'Connection to 103.247.238.92 timed out. (connect timeout=30)'))"
cowidev.vax.incremental.barbados,,,2022-10-15T07:02:36,,
cowidev.vax.incremental.brazil,0.1,True,2022-10-15T07:02:36,,
cowidev.vax.incremental.bulgaria,6.35,True,2022-10-15T07:02:43,,
cowidev.vax.incremental.china,42.3,True,2022-10-15T07:03:20,,
cowidev.vax.incremental.costa_rica,,,2022-10-15T07:02:43,,
cowidev.vax.incremental.croatia,0.56,True,2022-10-15T07:02:43,,
cowidev.vax.incremental.cuba,6.41,True,2022-10-15T07:02:50,,
cowidev.vax.incremental.curacao,0.44,True,2022-10-15T07:02:50,,
cowidev.vax.incremental.cyprus,1.14,True,2022-10-15T07:02:51,,
cowidev.vax.incremental.dominican_republic,6.87,True,2022-10-15T07:02:58,,
cowidev.vax.incremental.el_salvador,1.54,True,2022-10-15T07:03:00,,
cowidev.vax.incremental.faeroe_islands,0.58,True,2022-10-15T07:03:00,,
cowidev.vax.incremental.fiji,0.0,True,2022-10-15T07:03:00,,
cowidev.vax.incremental.finland,0.26,True,2022-10-15T07:03:01,,
cowidev.vax.incremental.gabon,,,2022-10-15T07:03:01,,
cowidev.vax.incremental.georgia,0.98,True,2022-10-15T07:03:02,,
cowidev.vax.incremental.greenland,0.72,False,2022-10-15T07:04:57,"Traceback (most recent call last):
  File ""/mnt/owid_live_covid/covid-19-data/scripts/src/cowidev/cmd/commons/get.py"", line 46, in run
    module.main()
  File ""/mnt/owid_live_covid/covid-19-data/scripts/src/cowidev/vax/incremental/greenland.py"", line 74, in main
    Greenland().export()
  File ""/mnt/owid_live_covid/covid-19-data/scripts/src/cowidev/vax/incremental/greenland.py"", line 61, in export
    data = self.read().pipe(self.pipeline)
  File ""/mnt/owid_live_covid/covid-19-data/scripts/src/cowidev/vax/incremental/greenland.py"", line 18, in read
    data = self._parse_data(soup)
  File ""/mnt/owid_live_covid/covid-19-data/scripts/src/cowidev/vax/incremental/greenland.py"", line 22, in _parse_data
    return {**self._parse_data_metrics(soup), **self._parse_data_date(soup)}
  File ""/mnt/owid_live_covid/covid-19-data/scripts/src/cowidev/vax/incremental/greenland.py"", line 26, in _parse_data_metrics
    dose_1 = clean_count(re.search(r""Innuttaasut ([\d\.]+)"", counters[1].parent.find_all(""dd"")[-1].text).group(1))
IndexError: list index out of range
",list index out of range
cowidev.vax.incremental.guatemala,,,2022-10-15T07:03:02,,
cowidev.vax.incremental.guernsey,0.33,True,2022-10-15T07:03:02,,
cowidev.vax.incremental.hungary,1.49,True,2022-10-15T07:03:03,,
cowidev.vax.incremental.iceland,0.93,True,2022-10-15T07:03:03,,
cowidev.vax.incremental.india,1.29,True,2022-10-15T07:03:05,,
cowidev.vax.incremental.iran,,,2022-10-15T07:03:03,,
cowidev.vax.incremental.isle_of_man,1.08,True,2022-10-15T07:03:05,,
cowidev.vax.incremental.jamaica,2.07,True,2022-10-15T07:03:07,,
cowidev.vax.incremental.kazakhstan,8.32,True,2022-10-15T07:03:13,,
cowidev.vax.incremental.kosovo,1.19,True,2022-10-15T07:03:08,,
cowidev.vax.incremental.kyrgyzstan,1.15,True,2022-10-15T07:03:08,,
cowidev.vax.incremental.laos,2.94,True,2022-10-15T07:03:10,,
cowidev.vax.incremental.macao,20.2,False,2022-10-15T07:05:17,"Traceback (most recent call last):
  File ""/mnt/owid_live_covid/covid-19-data/scripts/src/cowidev/cmd/commons/get.py"", line 46, in run
    module.main()
  File ""/mnt/owid_live_covid/covid-19-data/scripts/src/cowidev/vax/incremental/macao.py"", line 86, in main
    Macao().export()
  File ""/mnt/owid_live_covid/covid-19-data/scripts/src/cowidev/vax/incremental/macao.py"", line 72, in export
    data = self.read()
  File ""/mnt/owid_live_covid/covid-19-data/scripts/src/cowidev/vax/incremental/macao.py"", line 20, in read
    elem = driver.find_element_by_partial_link_text(""Weekly Bulletin on COVID-19"")
  File ""/mnt/owid_live_covid/covid-19-data/scripts/venv/lib/python3.9/site-packages/selenium/webdriver/remote/webdriver.py"", line 462, in find_element_by_partial_link_text
    return self.find_element(by=By.PARTIAL_LINK_TEXT, value=link_text)
  File ""/mnt/owid_live_covid/covid-19-data/scripts/venv/lib/python3.9/site-packages/selenium/webdriver/remote/webdriver.py"", line 976, in find_element
    return self.execute(Command.FIND_ELEMENT, {
  File ""/mnt/owid_live_covid/covid-19-data/scripts/venv/lib/python3.9/site-packages/selenium/webdriver/remote/webdriver.py"", line 321, in execute
    self.error_handler.check_response(response)
  File ""/mnt/owid_live_covid/covid-19-data/scripts/venv/lib/python3.9/site-packages/selenium/webdriver/remote/errorhandler.py"", line 242, in check_response
    raise exception_class(message, screen, stacktrace)
selenium.common.exceptions.NoSuchElementException: Message: no such element: Unable to locate element: {""method"":""partial link text"",""selector"":""Weekly Bulletin on COVID-19""}
  (Session info: headless chrome=105.0.5195.102)

","Message: no such element: Unable to locate element: {""method"":""partial link text"",""selector"":""Weekly Bulletin on COVID-19""}
  (Session info: headless chrome=105.0.5195.102)
"
cowidev.vax.incremental.moldova,,,2022-10-15T07:03:10,,
cowidev.vax.incremental.monaco,39.68,True,2022-10-15T07:03:50,,
cowidev.vax.incremental.mongolia,0.7,True,2022-10-15T07:03:14,,
cowidev.vax.incremental.montenegro,0.11,True,2022-10-15T07:03:14,,
cowidev.vax.incremental.morocco,,,2022-10-15T07:03:14,,
cowidev.vax.incremental.myanmar,,,2022-10-15T07:03:14,,
cowidev.vax.incremental.nepal,,,2022-10-15T07:03:14,,
cowidev.vax.incremental.north_macedonia,,,2022-10-15T07:03:14,,
cowidev.vax.incremental.northern_cyprus,0.96,True,2022-10-15T07:03:15,,
cowidev.vax.incremental.paho,40.06,False,2022-10-15T07:05:57,"Traceback (most recent call last):
  File ""/mnt/owid_live_covid/covid-19-data/scripts/venv/lib/python3.9/site-packages/urllib3/connection.py"", line 174, in _new_conn
    conn = connection.create_connection(
  File ""/mnt/owid_live_covid/covid-19-data/scripts/venv/lib/python3.9/site-packages/urllib3/util/connection.py"", line 96, in create_connection
    raise err
  File ""/mnt/owid_live_covid/covid-19-data/scripts/venv/lib/python3.9/site-packages/urllib3/util/connection.py"", line 86, in create_connection
    sock.connect(sa)
socket.timeout: timed out

During handling of the above exception, another exception occurred:

Traceback (most recent call last):
  File ""/mnt/owid_live_covid/covid-19-data/scripts/venv/lib/python3.9/site-packages/urllib3/connectionpool.py"", line 699, in urlopen
    httplib_response = self._make_request(
  File ""/mnt/owid_live_covid/covid-19-data/scripts/venv/lib/python3.9/site-packages/urllib3/connectionpool.py"", line 382, in _make_request
    self._validate_conn(conn)
  File ""/mnt/owid_live_covid/covid-19-data/scripts/venv/lib/python3.9/site-packages/urllib3/connectionpool.py"", line 1010, in _validate_conn
    conn.connect()
  File ""/mnt/owid_live_covid/covid-19-data/scripts/venv/lib/python3.9/site-packages/urllib3/connection.py"", line 358, in connect
    conn = self._new_conn()
  File ""/mnt/owid_live_covid/covid-19-data/scripts/venv/lib/python3.9/site-packages/urllib3/connection.py"", line 179, in _new_conn
    raise ConnectTimeoutError(
urllib3.exceptions.ConnectTimeoutError: (<urllib3.connection.HTTPSConnection object at 0x7f3acd2c97c0>, 'Connection to ais.paho.org timed out. (connect timeout=20)')

During handling of the above exception, another exception occurred:

Traceback (most recent call last):
  File ""/mnt/owid_live_covid/covid-19-data/scripts/venv/lib/python3.9/site-packages/requests/adapters.py"", line 440, in send
    resp = conn.urlopen(
  File ""/mnt/owid_live_covid/covid-19-data/scripts/venv/lib/python3.9/site-packages/urllib3/connectionpool.py"", line 755, in urlopen
    retries = retries.increment(
  File ""/mnt/owid_live_covid/covid-19-data/scripts/venv/lib/python3.9/site-packages/urllib3/util/retry.py"", line 574, in increment
    raise MaxRetryError(_pool, url, error or ResponseError(cause))
urllib3.exceptions.MaxRetryError: HTTPSConnectionPool(host='ais.paho.org', port=443): Max retries exceeded with url: /imm/IM_DosisAdmin-Vacunacion.asp (Caused by ConnectTimeoutError(<urllib3.connection.HTTPSConnection object at 0x7f3acd2c97c0>, 'Connection to ais.paho.org timed out. (connect timeout=20)'))

During handling of the above exception, another exception occurred:

Traceback (most recent call last):
  File ""/mnt/owid_live_covid/covid-19-data/scripts/src/cowidev/cmd/commons/get.py"", line 46, in run
    module.main()
  File ""/mnt/owid_live_covid/covid-19-data/scripts/src/cowidev/vax/incremental/paho.py"", line 191, in main
    PAHO().export()
  File ""/mnt/owid_live_covid/covid-19-data/scripts/src/cowidev/vax/incremental/paho.py"", line 186, in export
    df = self.read().pipe(self.pipeline)
  File ""/mnt/owid_live_covid/covid-19-data/scripts/src/cowidev/vax/incremental/paho.py"", line 36, in read
    url = self._parse_iframe_link()
  File ""/mnt/owid_live_covid/covid-19-data/scripts/src/cowidev/vax/incremental/paho.py"", line 41, in _parse_iframe_link
    html = get_soup(self.source_url)
  File ""/mnt/owid_live_covid/covid-19-data/scripts/src/cowidev/utils/web/scraping.py"", line 83, in get_soup
    response = get_response(source, request_method, use_proxy, **kwargs)
  File ""/mnt/owid_live_covid/covid-19-data/scripts/src/cowidev/utils/web/scraping.py"", line 49, in get_response
    raise err
  File ""/mnt/owid_live_covid/covid-19-data/scripts/src/cowidev/utils/web/scraping.py"", line 43, in get_response
    response = requests.get(source, **kwargs)
  File ""/mnt/owid_live_covid/covid-19-data/scripts/venv/lib/python3.9/site-packages/requests/api.py"", line 75, in get
    return request('get', url, params=params, **kwargs)
  File ""/mnt/owid_live_covid/covid-19-data/scripts/venv/lib/python3.9/site-packages/requests/api.py"", line 61, in request
    return session.request(method=method, url=url, **kwargs)
  File ""/mnt/owid_live_covid/covid-19-data/scripts/venv/lib/python3.9/site-packages/requests/sessions.py"", line 529, in request
    resp = self.send(prep, **send_kwargs)
  File ""/mnt/owid_live_covid/covid-19-data/scripts/venv/lib/python3.9/site-packages/requests/sessions.py"", line 645, in send
    r = adapter.send(request, **kwargs)
  File ""/mnt/owid_live_covid/covid-19-data/scripts/venv/lib/python3.9/site-packages/requests/adapters.py"", line 507, in send
    raise ConnectTimeout(e, request=request)
requests.exceptions.ConnectTimeout: HTTPSConnectionPool(host='ais.paho.org', port=443): Max retries exceeded with url: /imm/IM_DosisAdmin-Vacunacion.asp (Caused by ConnectTimeoutError(<urllib3.connection.HTTPSConnection object at 0x7f3acd2c97c0>, 'Connection to ais.paho.org timed out. (connect timeout=20)'))
","HTTPSConnectionPool(host='ais.paho.org', port=443): Max retries exceeded with url: /imm/IM_DosisAdmin-Vacunacion.asp (Caused by ConnectTimeoutError(<urllib3.connection.HTTPSConnection object at 0x7f3acd2c97c0>, 'Connection to ais.paho.org timed out. (connect timeout=20)'))"
cowidev.vax.incremental.pakistan,1.35,True,2022-10-15T07:03:21,,
cowidev.vax.incremental.philippines,,,2022-10-15T07:03:21,,
cowidev.vax.incremental.poland,0.29,True,2022-10-15T07:03:21,,
cowidev.vax.incremental.qatar,,,2022-10-15T07:03:21,,
cowidev.vax.incremental.russia,0.52,False,2022-10-15T07:05:58,"Traceback (most recent call last):
  File ""/mnt/owid_live_covid/covid-19-data/scripts/src/cowidev/cmd/commons/get.py"", line 46, in run
    module.main()
  File ""/mnt/owid_live_covid/covid-19-data/scripts/src/cowidev/vax/incremental/russia.py"", line 80, in main
    Russia().export()
  File ""/mnt/owid_live_covid/covid-19-data/scripts/src/cowidev/vax/incremental/russia.py"", line 66, in export
    data = read(source).pipe(pipeline)
  File ""/mnt/owid_live_covid/covid-19-data/scripts/src/cowidev/vax/incremental/russia.py"", line 11, in read
    soup = get_soup(source)
  File ""/mnt/owid_live_covid/covid-19-data/scripts/src/cowidev/utils/web/scraping.py"", line 83, in get_soup
    response = get_response(source, request_method, use_proxy, **kwargs)
  File ""/mnt/owid_live_covid/covid-19-data/scripts/src/cowidev/utils/web/scraping.py"", line 52, in get_response
    raise ValueError(
ValueError: Source https://gogov.ru/articles/covid-v-stats not reached! Error code 502 Bad Gateway
",Source https://gogov.ru/articles/covid-v-stats not reached! Error code 502 Bad Gateway
cowidev.vax.incremental.saint_lucia,,,2022-10-15T07:03:22,,
cowidev.vax.incremental.serbia,5.3,True,2022-10-15T07:03:27,,
cowidev.vax.incremental.south_africa,8.04,True,2022-10-15T07:03:35,,
cowidev.vax.incremental.spain,7.4,True,2022-10-15T07:03:35,,
cowidev.vax.incremental.sri_lanka,,,2022-10-15T07:03:35,,
cowidev.vax.incremental.suriname,14.47,True,2022-10-15T07:03:50,,
cowidev.vax.incremental.taiwan,6.05,True,2022-10-15T07:03:42,,
cowidev.vax.incremental.thailand,4.38,True,2022-10-15T07:03:41,,
cowidev.vax.incremental.turkey,0.68,True,2022-10-15T07:03:41,,
cowidev.vax.incremental.united_arab_emirates,,,2022-10-15T07:03:41,,
cowidev.vax.incremental.vietnam,,,2022-10-15T07:03:41,,
cowidev.vax.incremental.who,5.41,True,2022-10-15T07:03:47,,
cowidev.vax.incremental.zambia,0.97,True,2022-10-15T07:03:43,,
